Workbook

Sheet Cover
B2: ASIAN PAINTS LTD (ASIANPAINT)
B3: Integrated Three-Statement Financial Model & Valuation
B6: Company | C6: Asian Paints Ltd (NSE: ASIANPAINT, BSE: 500820) | D6: BLUE - Constants
B7: Sector | C7: Paints & Home Décor (Consumer Discretionary) | D7: BLACK - Formulas (same sheet)
B8: Historical Period | C8: FY2022 – FY2026 (year ending 31 March) | D8: GREEN - Links to other sheets
B9: Forecast Period | C9: FY2027E – FY2031E
B10: Valuation Methods | C10: Discounted Cash Flow (FCFF) + Relative Valuation (Comparables)
B11: Prepared As On | C11: 18 August 2026
B12: Currency | C12: INR Crores unless stated otherwise
B13: Primary Data Sources | C13: screener.in (consolidated) · ICICI Direct Q4FY26 Result Update · Company Investor Relations
B15: Workbook Map
B16: Historical Data | C16: 5-year historical IS / BS / CF, ratios, market snapshot
B17: Ratio Analysis | C17: Liquidity, solvency, profitability, turnover, earnings ratios
B18: Assumptions | C18: Forecast drivers with justification
B19: Working Capital Schedule | C19: Receivables / inventory / payables via days assumptions
B20: Dep & Capex Schedule | C20: Asset roll-forward: capex additions, depreciation
B21: Debt Schedule | C21: Debt roll-forward, repayments, interest expense
B22: Income Statement | C22: Projected P&L FY27E-FY31E
B23: Balance Sheet | C23: Projected balance sheet (balances by construction)
B24: Cash Flow | C24: Projected cash flow (cash links back to balance sheet)
B25: Valuation | C25: DCF (FCFF) + relative valuation + football field
B26: Recommendation | C26: Buy / Hold / Sell with rationale and risks

Sheet Historical Data
A1: HISTORICAL FINANCIALS
B2: (All figures in ₹ Crores except per-share data) | C2: FY2022 | D2: FY2023 | E2: FY2024 | F2: FY2025 | G2: FY2026
B4: 1. INCOME STATEMENT (₹ Cr)
B5: ₹ Crores | C5: FY2022 | D5: FY2023 | E5: FY2024 | F5: FY2025 | G5: FY2026
B6: Revenue from Operations (Sales) | C6: 29101 | D6: 34489 | E6: 35495 | F6: 33906 | G6: 35584
B7: Total Operating Expenses | C7: 24298 | D7: 28229 | E7: 27910 | F7: 27899 | G7: 28884
B8: EBITDA (Operating Profit) | C8: =C6-C7 -> 4803 | D8: =D6-D7 -> 6260 | E8: =E6-E7 -> 7585 | F8: =F6-F7 -> 6007 | G8: =G6-G7 -> 6700
B9: EBITDA Margin % | C9: =C8/C6 -> 0.16504587 | D9: =D8/D6 -> 0.18150715 | E9: =E8/E6 -> 0.21369207 | F9: =F8/F6 -> 0.17716628 | G9: =G8/G6 -> 0.18828687
B10: Other Income | C10: 296 | D10: 431 | E10: 821 | F10: 350 | G10: 728
B11: Interest (Finance Costs) | C11: 95 | D11: 144 | E11: 205 | F11: 227 | G11: 195
B12: Depreciation & Amortisation | C12: 816 | D12: 858 | E12: 853 | F12: 1026 | G12: 1229
B13: Profit Before Tax | C13: =C8+C10-C11-C12 -> 4188 | D13: =D8+D10-D11-D12 -> 5689 | E13: =E8+E10-E11-E12 -> 7348 | F13: =F8+F10-F11-F12 -> 5104 | G13: =G8+G10-G11-G12 -> 6004
B14: Effective Tax Rate % | C14: 0.26 | D14: 0.26 | E14: 0.24 | F14: 0.27 | G14: 0.27
B15: Net Profit (incl. associates & MI) | C15: 3085 | D15: 4195 | E15: 5558 | F15: 3710 | G15: 4395
B16: Net Profit Margin % | C16: =C15/C6 -> 0.1060101 | D16: =D15/D6 -> 0.12163298 | E16: =E15/E6 -> 0.15658543 | F16: =F15/F6 -> 0.10942016 | G16: =G15/G6 -> 0.12351057
B17: EPS (₹) | C17: 31.59 | D17: 42.81 | E17: 56.92 | F17: 38.23 | G17: 45.09
B18: Dividend Payout % | C18: 0.61 | D18: 0.6 | E18: 0.58 | F18: 0.65 | G18: 0.61
B19: Revenue Growth % YoY | D19: =D6/C6-1 -> 0.18514828 | E19: =E6/D6-1 -> 0.02916872 | F19: =F6/E6-1 -> -0.044766869 | G19: =G6/F6-1 -> 0.049489766
B21: 2. BALANCE SHEET (₹ Cr)
B22: ₹ Crores | C22: FY2022 | D22: FY2023 | E22: FY2024 | F22: FY2025 | G22: FY2026
B23: Equity Share Capital | C23: 96 | D23: 96 | E23: 96 | F23: 96 | G23: 96
B24: Reserves & Surplus | C24: 13716 | D24: 15896 | E24: 18632 | F24: 19304 | G24: 21276
B25: Net Worth (Shareholders' Funds) | C25: =C23+C24 -> 13812 | D25: =D23+D24 -> 15992 | E25: =E23+E24 -> 18728 | F25: =F23+F24 -> 19400 | G25: =G23+G24 -> 21372
B26: Borrowings (incl. lease liabilities) | C26: 1587 | D26: 1933 | E26: 2474 | F26: 2290 | G26: 3929
B27: Other Liabilities & Provisions | C27: 7560 | D27: 7854 | E27: 8698 | F27: 8665 | G27: 9218
B28: Total Equity & Liabilities | C28: =C25+C26+C27 -> 22959 | D28: =D25+D26+D27 -> 25779 | E28: =E25+E26+E27 -> 29900 | F28: =F25+F26+F27 -> 30355 | G28: =G25+G26+G27 -> 34519
B29: Net Fixed Assets (incl. intangibles, ROU) | C29: 5519 | D29: 5770 | E29: 7147 | F29: 9220 | G29: 9640
B30: Capital Work-in-Progress | C30: 426 | D30: 1020 | E30: 2698 | F30: 1254 | G30: 1849
B31: Investments (non-current + current) | C31: 3248 | D31: 4262 | E31: 4588 | F31: 4725 | G31: 7062
B32: Other Assets (incl. WC, cash; rounding-adjusted) | C32: 13766 | D32: 14727 | E32: 15467 | F32: 15156 | G32: 15968
B33: Total Assets | C33: =C29+C30+C31+C32 -> 22959 | D33: =D29+D30+D31+D32 -> 25779 | E33: =E29+E30+E31+E32 -> 29900 | F33: =F29+F30+F31+F32 -> 30355 | G33: =G29+G30+G31+G32 -> 34519
B34: Balance Check (must be 0) | C34: =C28-C33 -> 0 | D34: =D28-D33 -> 0 | E34: =E28-E33 -> 0 | F34: =F28-F33 -> 0 | G34: =G28-G33 -> 0
B36: 3. CASH FLOW STATEMENT (₹ Cr)
B37: ₹ Crores | C37: FY2022 | D37: FY2023 | E37: FY2024 | F37: FY2025 | G37: FY2026
B38: Cash from Operating Activities | C38: 986 | D38: 4193 | E38: 6104 | F38: 4424 | G38: 7088
B39: Cash from Investing Activities | C39: -317 | D39: -1282 | E39: -2548 | F39: -941 | G39: -1328
B40: Cash from Financing Activities | C40: -1808 | D40: -2140 | E40: -2982 | F40: -3753 | G40: -2377
B41: Net Change in Cash | C41: =C38+C39+C40 -> -1139 | D41: =D38+D39+D40 -> 771 | E41: =E38+E39+E40 -> 574 | F41: =F38+F39+F40 -> -270 | G41: =G38+G39+G40 -> 3383
B42: Free Cash Flow (screener) | C42: 475 | D42: 2774 | E42: 3613 | F42: 2604 | G42: 5604
B44: 4. WORKING-CAPITAL / EFFICIENCY METRICS (screener)
...

Sheet Ratio Analysis
A1: RATIO ANALYSIS | C1: Historicals | H1: Forecasts
B2: (All figures in ₹ Crores except per-share data) | C2: FY2022 | D2: FY2023 | E2: FY2024 | F2: FY2025 | G2: FY2026 | H2: FY27E | I2: FY28E | J2: FY29E | K2: FY30E | L2: FY31E
B3: LIQUIDITY RATIOS
M4: Trend | N4: Interpretation
B5: Current ratio (approx) (times) | C5: ='Historical Data'!C32/'Historical Data'!C27 -> 1.8208995 | D5: ='Historical Data'!D32/'Historical Data'!D27 -> 1.8750955 | E5: ='Historical Data'!E32/'Historical Data'!E27 -> 1.7782249 | F5: ='Historical Data'!F32/'Historical Data'!F27 -> 1.7491056 | G5: ='Historical Data'!G32/'Historical Data'!G27 -> 1.732263 | H5: =('Balance Sheet'!D8+'Balance Sheet'!D9+'Balance Sheet'!D10+'Balance Sheet'!D11)/('Balance Sheet'!D21+'Balance Sheet'!D22) -> 1.771435 | I5: =('Balance Sheet'!E8+'Balance Sheet'!E9+'Balance Sheet'!E10+'Balance Sheet'!E11)/('Balance Sheet'!E21+'Balance Sheet'!E22) -> 1.8414785 | J5: =('Balance Sheet'!F8+'Balance Sheet'!F9+'Balance Sheet'!F10+'Balance Sheet'!F11)/('Balance Sheet'!F21+'Balance Sheet'!F22) -> 1.9313584 | K5: =('Balance Sheet'!G8+'Balance Sheet'!G9+'Balance Sheet'!G10+'Balance Sheet'!G11)/('Balance Sheet'!G21+'Balance Sheet'!G22) -> 2.0154572 | L5: =('Balance Sheet'!H8+'Balance Sheet'!H9+'Balance Sheet'!H10+'Balance Sheet'!H11)/('Balance Sheet'!H21+'Balance Sheet'!H22) -> 2.0987428 | N5: The company always owns ~1.7–1.9 times more short-term assets than the bills it owes — past and forecast.
B6: Quick ratio (approx) (times) | E6: =('Historical Data'!E32-'Historical Data'!C55)/'Historical Data'!E27 -> 1.0972178 | F6: =('Historical Data'!F32-'Historical Data'!D55)/'Historical Data'!F27 -> 0.97365263 | G6: =('Historical Data'!G32-'Historical Data'!E55)/'Historical Data'!G27 -> 1.1091668 | H6: =('Balance Sheet'!D9+'Balance Sheet'!D10+'Balance Sheet'!D11)/('Balance Sheet'!D21+'Balance Sheet'!D22) -> 1.1515388 | I6: =('Balance Sheet'!E9+'Balance Sheet'!E10+'Balance Sheet'!E11)/('Balance Sheet'!E21+'Balance Sheet'!E22) -> 1.2319236 | J6: =('Balance Sheet'!F9+'Balance Sheet'!F10+'Balance Sheet'!F11)/('Balance Sheet'!F21+'Balance Sheet'!F22) -> 1.3321032 | K6: =('Balance Sheet'!G9+'Balance Sheet'!G10+'Balance Sheet'!G11)/('Balance Sheet'!G21+'Balance Sheet'!G22) -> 1.4256103 | L6: =('Balance Sheet'!H9+'Balance Sheet'!H10+'Balance Sheet'!H11)/('Balance Sheet'!H21+'Balance Sheet'!H22) -> 1.5187007 | N6: Even without counting paint stock, short-term bills stay covered (~1.0–1.2 times).
B7: Cash + investments (₹ Cr) | E7: ='Historical Data'!C57+'Historical Data'!C58 -> 4287.3 | F7: ='Historical Data'!D57+'Historical Data'!D58 -> 4027 | G7: ='Historical Data'!E57+'Historical Data'!E58 -> 7359.6 | H7: ='Balance Sheet'!D10+'Balance Sheet'!D7 -> 8755.0993 | I7: ='Balance Sheet'!E10+'Balance Sheet'!E7 -> 9846.3464 | J7: ='Balance Sheet'!F10+'Balance Sheet'!F7 -> 11368.618 | K7: ='Balance Sheet'!G10+'Balance Sheet'!G7 -> 13061.703 | L7: ='Balance Sheet'!H10+'Balance Sheet'!H7 -> 14979.488 | N7: The ready-money pile keeps compounding — ~₹4,300 Cr (FY24) to ~₹15,000 Cr by FY31, even after big dividends. (Forecast includes ₹776 Cr non-current investments.)
B9: SOLVENCY RATIOS
M10: Trend | N10: Interpretation
B11: Debt / equity (times) | C11: ='Historical Data'!C26/'Historical Data'!C25 -> 0.11490009 | D11: ='Historical Data'!D26/'Historical Data'!D25 -> 0.12087294 | E11: ='Historical Data'!E26/'Historical Data'!E25 -> 0.13210167 | F11: ='Historical Data'!F26/'Historical Data'!F25 -> 0.11804124 | G11: ='Historical Data'!G26/'Historical Data'!G25 -> 0.18383867 | H11: =('Balance Sheet'!D19+'Balance Sheet'!D20)/'Balance Sheet'!D18 -> 0.16884233 | I11: =('Balance Sheet'!E19+'Balance Sheet'!E20)/'Balance Sheet'!E18 -> 0.15431812 | J11: =('Balance Sheet'!F19+'Balance Sheet'!F20)/'Balance Sheet'!F18 -> 0.14048476 | K11: =('Balance Sheet'!G19+'Balance Sheet'!G20)/'Balance Sheet'!G18 -> 0.12760766 | L11: =('Balance Sheet'!H19+'Balance Sheet'!H20)/'Balance Sheet'!H18 -> 0.1156995 | N11: Debt (incl. leases) stays tiny — 0.11–0.18 times — and shrinks further as net worth grows.
B12: Debt / EBITDA (times) | C12: ='Historical Data'!C26/'Historical Data'!C8 -> 0.33041849 | D12: ='Historical Data'!D26/'Historical Data'!D8 -> 0.30878594 | E12: ='Historical Data'!E26/'Historical Data'!E8 -> 0.32617007 | F12: ='Historical Data'!F26/'Historical Data'!F8 -> 0.38122191 | G12: ='Historical Data'!G26/'Historical Data'!G8 -> 0.58641791 | H12: =('Balance Sheet'!D19+'Balance Sheet'!D20)/'Income Statement'!D7 -> 0.53686719 | I12: =('Balance Sheet'!E19+'Balance Sheet'!E20)/'Income Statement'!E7 -> 0.47316045 | J12: =('Balance Sheet'!F19+'Balance Sheet'!F20)/'Income Statement'!F7 -> 0.4209897 | K12: =('Balance Sheet'!G19+'Balance Sheet'!G20)/'Income Statement'!G7 -> 0.38041025 | L12: =('Balance Sheet'!H19+'Balance Sheet'!H20)/'Income Statement'!H7 -> 0.34362233 | N12: All debt equals only ~4–7 months of operating profit, in every single year.
B13: Interest coverage (times) | C13: =('Historical Data'!C13+'Historical Data'!C11)/'Historical Data'!C11 -> 45.084211 | D13: =('Historical Data'!D13+'Historical Data'!D11)/'Historical Data'!D11 -> 40.506944 | E13: =('Historical Data'!E13+'Historical Data'!E11)/'Historical Data'!E11 -> 36.843902 | F13: =('Historical Data'!F13+'Historical Data'!F11)/'Historical Data'!F11 -> 23.484581 | G13: =('Historical Data'!G13+'Historical Data'!G11)/'Historical Data'!G11 -> 31.789744 | H13: =('Income Statement'!D12+'Income Statement'!D11)/'Income Statement'!D11 -> 26.281696 | I13: =('Income Statement'!E12+'Income Statement'!E11)/'Income Statement'!E11 -> 30.169822 | J13: =('Income Statement'!F12+'Income Statement'!F11)/'Income Statement'!F11 -> 34.39034 | K13: =('Income Statement'!G12+'Income Statement'!G11)/'Income Statement'!G11 -> 38.588191 | L13: =('Income Statement'!H12+'Income Statement'!H11)/'Income Statement'!H11 -> 43.206133 | N13: Profit covers the interest bill 24–45 times, improving to ~43 times — zero default risk.
B14: Equity ratio (net worth / assets) % | C14: ='Historical Data'!C25/'Historical Data'!C33 -> 0.60159415 | D14: ='Historical Data'!D25/'Historical Data'!D33 -> 0.6203499 | E14: ='Historical Data'!E25/'Historical Data'!E33 -> 0.62635452 | F14: ='Historical Data'!F25/'Historical Data'!F33 -> 0.63910394 | G14: ='Historical Data'!G25/'Historical Data'!G33 -> 0.61913729 | H14: ='Balance Sheet'!D18/'Balance Sheet'!D12 -> 0.61780266 | I14: ='Balance Sheet'!E18/'Balance Sheet'!E12 -> 0.62119456 | J14: ='Balance Sheet'!F18/'Balance Sheet'!F12 -> 0.62665715 | K14: ='Balance Sheet'!G18/'Balance Sheet'!G12 -> 0.63289621 | L14: ='Balance Sheet'!H18/'Balance Sheet'!H12 -> 0.64014568 | N14: 60%+ of everything the company owns is funded by shareholders, throughout.
B15: Net debt (₹ Cr) | E15: ='Historical Data'!E26-'Historical Data'!C57-'Historical Data'!C58 -> -1813.3 | F15: ='Historical Data'!F26-'Historical Data'!D57-'Historical Data'!D58 -> -1737 | G15: ='Historical Data'!G26-'Historical Data'!E57-'Historical Data'!E58 -> -3430.6 | H15: ='Balance Sheet'!D19+'Balance Sheet'!D20-'Balance Sheet'!D10-'Balance Sheet'!D7 -> -4826.0993 | I15: ='Balance Sheet'!E19+'Balance Sheet'!E20-'Balance Sheet'!E10-'Balance Sheet'!E7 -> -5917.3464 | J15: ='Balance Sheet'!F19+'Balance Sheet'!F20-'Balance Sheet'!F10-'Balance Sheet'!F7 -> -7439.6177 | K15: ='Balance Sheet'!G19+'Balance Sheet'!G20-'Balance Sheet'!G10-'Balance Sheet'!G7 -> -9132.7034 | L15: ='Balance Sheet'!H19+'Balance Sheet'!H20-'Balance Sheet'!H10-'Balance Sheet'!H7 -> -11050.488 | N15: Always negative = more cash than debt; the surplus roughly triples to ~₹11,000 Cr by FY31.
B17: PROFITABILITY RATIOS
M18: Trend | N18: Interpretation
B19: EBITDA margin % | C19: ='Historical Data'!C9 -> 0.16504587 | D19: ='Historical Data'!D9 -> 0.18150715 | E19: ='Historical Data'!E9 -> 0.21369207 | F19: ='Historical Data'!F9 -> 0.17716628 | G19: ='Historical Data'!G9 -> 0.18828687 | H19: ='Income Statement'!D8 -> 0.182 | I19: ='Income Statement'!E8 -> 0.186 | J19: ='Income Statement'!F8 -> 0.19 | K19: ='Income Statement'!G8 -> 0.192 | L19: ='Income Statement'!H8 -> 0.195 | N19: Fell to 16.5% in FY22's cost shock, peaked at 21.4% in FY24, then holds inside the promised 18–20% band.
B20: Net profit margin % | C20: ='Historical Data'!C16 -> 0.1060101 | D20: ='Historical Data'!D16 -> 0.12163298 | E20: ='Historical Data'!E16 -> 0.15658543 | F20: ='Historical Data'!F16 -> 0.10942016 | G20: ='Historical Data'!G16 -> 0.12351057 | H20: ='Income Statement'!D15 -> 0.11801716 | I20: ='Income Statement'!E15 -> 0.1226467 | J20: ='Income Statement'!F15 -> 0.1275988 | K20: ='Income Statement'!G15 -> 0.13116125 | L20: ='Income Statement'!H15 -> 0.13511148 | N20: ₹10–16 of every ₹100 of sales becomes final profit; settles around 13% in the forecasts.
B21: Return on equity (ROE) % | C21: ='Historical Data'!C15/'Historical Data'!C25 -> 0.2233565 | D21: ='Historical Data'!D15/'Historical Data'!D25 -> 0.26231866 | E21: ='Historical Data'!E15/'Historical Data'!E25 -> 0.29677488 | F21: ='Historical Data'!F15/'Historical Data'!F25 -> 0.19123711 | G21: ='Historical Data'!G15/'Historical Data'!G25 -> 0.2056429 | H21: ='Income Statement'!D14/'Balance Sheet'!D18 -> 0.20393335 | I21: ='Income Statement'!E14/'Balance Sheet'!E18 -> 0.21505592 | J21: ='Income Statement'!F14/'Balance Sheet'!F18 -> 0.22410458 | K21: ='Income Statement'!G14/'Balance Sheet'!G18 -> 0.22915475 | L21: ='Income Statement'!H14/'Balance Sheet'!H18 -> 0.23329624 | N21: Shareholders' money earned 19–30% historically and stays above 20% in the forecasts.
B22: ROCE % (closing capital) | C22: =('Historical Data'!C13+'Historical Data'!C11)/('Historical Data'!C25+'Historical Data'!C26) -> 0.27813494 | D22: =('Historical Data'!D13+'Historical Data'!D11)/('Historical Data'!D25+'Historical Data'!D26) -> 0.32541144 | E22: =('Historical Data'!E13+'Historical Data'!E11)/('Historical Data'!E25+'Historical Data'!E26) -> 0.35623998 | F22: =('Historical Data'!F13+'Historical Data'!F11)/('Historical Data'!F25+'Historical Data'!F26) -> 0.24578147 | G22: =('Historical Data'!G13+'Historical Data'!G11)/('Historical Data'!G25+'Historical Data'!G26) -> 0.24501008 | H22: =('Income Statement'!D12+'Income Statement'!D11)/('Balance Sheet'!D18+'Balance Sheet'!D19+'Balance Sheet'!D20) -> 0.24676988 | I22: =('Income Statement'!E12+'Income Statement'!E11)/('Balance Sheet'!E18+'Balance Sheet'!E19+'Balance Sheet'!E20) -> 0.26216669 | J22: =('Income Statement'!F12+'Income Statement'!F11)/('Balance Sheet'!F18+'Balance Sheet'!F19+'Balance Sheet'!F20) -> 0.27535283 | K22: =('Income Statement'!G12+'Income Statement'!G11)/('Balance Sheet'!G18+'Balance Sheet'!G19+'Balance Sheet'!G20) -> 0.28384843 | L22: =('Income Statement'!H12+'Income Statement'!H11)/('Balance Sheet'!H18+'Balance Sheet'!H19+'Balance Sheet'!H20) -> 0.29123462 | N22: Every working rupee earns 24–36 paise; recovers toward ~29% as the new plants start producing.
B23: ROCE % (screener reported) | C23: ='Historical Data'!C51 -> 0.29 | D23: ='Historical Data'!D51 -> 0.34 | E23: ='Historical Data'!E51 -> 0.38 | F23: ='Historical Data'!F51 -> 0.26 | G23: ='Historical Data'!G51 -> 0.26 | N23: Screener's average-capital version of the same story (history only).
B25: TURNOVER RATIOS
M26: Trend | N26: Interpretation
B27: Total asset turnover (times) | C27: ='Historical Data'!C6/'Historical Data'!C33 -> 1.2675204 | D27: ='Historical Data'!D6/'Historical Data'!D33 -> 1.3378719 | E27: ='Historical Data'!E6/'Historical Data'!E33 -> 1.1871237 | F27: ='Historical Data'!F6/'Historical Data'!F33 -> 1.1169824 | G27: ='Historical Data'!G6/'Historical Data'!G33 -> 1.0308526 | H27: ='Income Statement'!D4/'Balance Sheet'!D12 -> 1.0675614 | I27: ='Income Statement'!E4/'Balance Sheet'!E12 -> 1.089239 | J27: ='Income Statement'!F4/'Balance Sheet'!F12 -> 1.1006117 | K27: ='Income Statement'!G4/'Balance Sheet'!G12 -> 1.105747 | L27: ='Income Statement'!H4/'Balance Sheet'!H12 -> 1.105336 | N27: Dipped during the downturn and capex phase; stabilises around 1.1 times.
B28: Fixed asset turnover (times) | C28: ='Historical Data'!C6/('Historical Data'!C29+'Historical Data'!C30) -> 4.8950378 | D28: ='Historical Data'!D6/('Historical Data'!D29+'Historical Data'!D30) -> 5.0793814 | E28: ='Historical Data'!E6/('Historical Data'!E29+'Historical Data'!E30) -> 3.6053834 | F28: ='Historical Data'!F6/('Historical Data'!F29+'Historical Data'!F30) -> 3.2371587 | G28: ='Historical Data'!G6/('Historical Data'!G29+'Historical Data'!G30) -> 3.0972234 | H28: ='Income Statement'!D4/'Balance Sheet'!D6 -> 3.3334897 | I28: ='Income Statement'!E4/'Balance Sheet'!E6 -> 3.5519088 | J28: ='Income Statement'!F4/'Balance Sheet'!F6 -> 3.7856319 | K28: ='Income Statement'!G4/'Balance Sheet'!G6 -> 3.9813951 | L28: ='Income Statement'!H4/'Balance Sheet'!H6 -> 4.1386441 | N28: Fell from ~5 times to ~3.1 times while factories were being built; recovers to ~4.1 times as VAM-VAE ramps.
B29: Receivable (debtor) days | C29: ='Historical Data'!C46 -> 49 | D29: ='Historical Data'!D46 -> 49 | E29: ='Historical Data'!E46 -> 50 | F29: ='Historical Data'!F46 -> 46 | G29: ='Historical Data'!G46 -> 46 | H29: =Assumptions!C21 -> 46 | I29: =Assumptions!D21 -> 46 | J29: =Assumptions!E21 -> 46 | K29: =Assumptions!F21 -> 46 | L29: =Assumptions!G21 -> 46 | N29: Customers pay in 46–50 days throughout — credit discipline holds.
B30: Inventory days (screener, on material cost) | C30: ='Historical Data'!C47 -> 142 | D30: ='Historical Data'!D47 -> 121 | E30: ='Historical Data'!E47 -> 122 | F30: ='Historical Data'!F47 -> 142 | G30: ='Historical Data'!G47 -> 118 | N30: Stock vs material COST — ~4 months; FY26's 118 days was the leanest in five years. (History only.)
B31: Inventory days (of operating costs) | E31: ='Historical Data'!C55/'Historical Data'!E7*365 -> 77.464744 | F31: ='Historical Data'!D55/'Historical Data'!F7*365 -> 87.907972 | G31: ='Historical Data'!E55/'Historical Data'!G7*365 -> 72.581723 | H31: =Assumptions!C22 -> 72 | I31: =Assumptions!D22 -> 71 | J31: =Assumptions!E22 -> 70 | K31: =Assumptions!F22 -> 69 | L31: =Assumptions!G22 -> 68 | N31: Stock measured against operating COST — ~2.5 months; FY25's 88 days was the bloat, FY26's ~73 the cleanest; assumptions ease it to 68 by FY31.
B32: Payable days (screener, on material cost) | C32: ='Historical Data'!C48 -> 96 | D32: ='Historical Data'!D48 -> 71 | E32: ='Historical Data'!E48 -> 79 | F32: ='Historical Data'!F48 -> 81 | G32: ='Historical Data'!G48 -> 79 | N32: Supplier credit vs material cost — 71–96 days. (History only.)
B33: Payable days (of operating costs) | E33: ='Historical Data'!C59/'Historical Data'!E7*365 -> 50.104783 | F33: ='Historical Data'!D59/'Historical Data'!F7*365 -> 50.343023 | G33: ='Historical Data'!E59/'Historical Data'!G7*365 -> 48.817044 | H33: =Assumptions!C23 -> 49 | I33: =Assumptions!D23 -> 49 | J33: =Assumptions!E23 -> 49 | K33: =Assumptions!F23 -> 49 | L33: =Assumptions!G23 -> 49 | N33: Supplier credit against costs — steady around 49 days; big buyers keep good terms.
B34: Cash conversion cycle (revenue basis) | E34: =E29+E31-E33 -> 77.359961 | F34: =F29+F31-F33 -> 83.564949 | G34: =G29+G31-G33 -> 69.764679 | H34: =H29+H31-H33 -> 69 | I34: =I29+I31-I33 -> 68 | J34: =J29+J31-J33 -> 67 | K34: =K29+K31-K33 -> 66 | L34: =L29+L31-L33 -> 65 | N34: Receivable + inventory − payable days: peaked ~84 in FY25, ~70 in FY26, improving to ~65 by FY31.
B35: Working capital days (screener) | C35: ='Historical Data'!C50 -> 57 | D35: ='Historical Data'!D50 -> 54 | E35: ='Historical Data'!E50 -> 49 | F35: ='Historical Data'!F50 -> 52 | G35: ='Historical Data'!G50 -> 38 | N35: Screener's working-capital days fell 57 → 38 — the big FY26 cash release. (History only.)
B37: EARNINGS RATIOS
M38: Trend | N38: Interpretation
B39: EPS (₹) | C39: ='Historical Data'!C17 -> 31.59 | D39: ='Historical Data'!D17 -> 42.81 | E39: ='Historical Data'!E17 -> 56.92 | F39: ='Historical Data'!F17 -> 38.23 | G39: ='Historical Data'!G17 -> 45.09 | H39: ='Income Statement'!D16 -> 49.474312 | I39: ='Income Statement'!E16 -> 57.083072 | J39: ='Income Statement'!F16 -> 65.342296 | K39: ='Income Statement'!G16 -> 73.557164 | L39: ='Income Statement'!H16 -> 82.594117 | N39: ₹31.6 → ₹45.1 over five years, then ~13% a year to ₹81.6 by FY31.
B40: EPS growth % | D40: =D39/C39-1 -> 0.35517569 | E40: =E39/D39-1 -> 0.32959589 | F40: =F39/E39-1 -> -0.32835559 | G40: =G39/F39-1 -> 0.17944023 | H40: =H39/G39-1 -> 0.097234677 | I40: =I39/H39-1 -> 0.15379215 | J40: =J39/I39-1 -> 0.14468779 | K40: =K39/J39-1 -> 0.12572053 | L40: =L39/K39-1 -> 0.12285619 | N40: Bumpy history (+35%, −33%); the forecast smooths out to 9–16% a year.
B41: Dividend per share (₹) | C41: ='Historical Data'!C17*'Historical Data'!C18 -> 19.2699 | D41: ='Historical Data'!D17*'Historical Data'!D18 -> 25.686 | E41: ='Historical Data'!E17*'Historical Data'!E18 -> 33.0136 | F41: ='Historical Data'!F17*'Historical Data'!F18 -> 24.8495 | G41: ='Historical Data'!G17*'Historical Data'!G18 -> 27.5049 | H41: ='Income Statement'!D17 -> 29.684587 | I41: ='Income Statement'!E17 -> 34.249843 | J41: ='Income Statement'!F17 -> 39.205378 | K41: ='Income Statement'!G17 -> 44.134298 | L41: ='Income Statement'!H17 -> 49.55647 | N41: The dividend follows profit at ~60% payout — ₹19 → ₹49 over the decade.
B42: Book value per share (₹) | C42: ='Historical Data'!C25/Assumptions!$C$8 -> 143.995 | D42: ='Historical Data'!D25/Assumptions!$C$8 -> 166.72227 | E42: ='Historical Data'!E25/Assumptions!$C$8 -> 195.24604 | F42: ='Historical Data'!F25/Assumptions!$C$8 -> 202.25188 | G42: ='Historical Data'!G25/Assumptions!$C$8 -> 222.81068 | H42: ='Balance Sheet'!D18/Assumptions!$C$8 -> 242.6004 | I42: ='Balance Sheet'!E18/Assumptions!$C$8 -> 265.43363 | J42: ='Balance Sheet'!F18/Assumptions!$C$8 -> 291.57055 | K42: ='Balance Sheet'!G18/Assumptions!$C$8 -> 320.99341 | L42: ='Balance Sheet'!H18/Assumptions!$C$8 -> 354.03106 | N42: Net worth per share compounds ~12% a year to ~₹353, even after the payouts.
B43: P/E at CMP ₹2,628 (times) | G43: =Assumptions!$C$7/G39 -> 58.283433 | H43: =Assumptions!$C$7/H39 -> 53.118475 | I43: =Assumptions!$C$7/I39 -> 46.038167 | J43: =Assumptions!$C$7/J39 -> 40.218972 | K43: =Assumptions!$C$7/K39 -> 35.727315 | L43: =Assumptions!$C$7/L39 -> 31.818247 | N43: At today's ₹2,628 you pay 58 times FY26 profit, 53 times FY27's, falling to 32 times FY31's — the price assumes the growth arrives.
B44: Dividend yield at CMP % | G44: =G39*'Historical Data'!G18/Assumptions!$C$7 -> 0.010466096 | H44: ='Income Statement'!D17/Assumptions!$C$7 -> 0.011295505 | I44: ='Income Statement'!E17/Assumptions!$C$7 -> 0.013032665 | J44: ='Income Statement'!F17/Assumptions!$C$7 -> 0.014918332 | K44: ='Income Statement'!G17/Assumptions!$C$7 -> 0.016793873 | L44: ='Income Statement'!H17/Assumptions!$C$7 -> 0.018857104 | N44: ~1.0% today, rising to ~1.9% on FY31's dividend — returns must come from growth, not yield.
...

Sheet Assumptions
A1: FORECASTING ASSUMPTIONS | C1: Forecasts
B2: (All figures in ₹ Crores except per-share data) | C2: FY27E | D2: FY28E | E2: FY29E | F2: FY30E | G2: FY31E
B4: GLOBAL / MARKET INPUTS
H5: Justification
B6: Valuation date | C6: 46252 | H6: The model uses market data as on this date.
B7: Current market price (₹) | C7: 2628 | H7: Share price on NSE on 18-Aug-2026 (from screener.in).
B8: Shares outstanding (Cr) | C8: 95.92 | H8: Total shares = ₹95.92 Cr equity capital ÷ ₹1 face value per share.
B10: OPERATING ASSUMPTIONS
H11: Justification
B12: Decorative volume growth % | C12: 0.085 | D12: 0.08 | E12: 0.075 | F12: 0.07 | G12: 0.065 | H12: Management guides 8–10% volume growth for FY27; we take 8.5%, easing to 6.5% as competition persists. Implies industry volume growth of ~7–9% with broadly stable market share after FY25's losses.
B13: Price / realisation / mix growth % | C13: 0.0415 | D13: 0.028 | E13: 0.0235 | F13: 0.0235 | G13: 0.0235 | H13: ~10.5–11% price hikes were taken in Q1FY27, but discounts compete much of it away; management expects the volume-value gap to settle at 3–4%. Net realisation gain ~4% in FY27, ~2.4% later.
B14: Revenue growth % | C14: =(1+C12)*(1+C13)-1 -> 0.1300275 | D14: =(1+D12)*(1+D13)-1 -> 0.11024 | E14: =(1+E12)*(1+E13)-1 -> 0.1002625 | F14: =(1+F12)*(1+F13)-1 -> 0.095145 | G14: =(1+G12)*(1+G13)-1 -> 0.0900275 | H14: Now CALCULATED as (1 + volume) × (1 + price/mix) − 1 — the top line is built from operating drivers, not asserted.
B15: EBITDA margin % | C15: 0.182 | D15: 0.186 | E15: 0.19 | F15: 0.192 | G15: 0.195 | H15: Management says margins will stay between 18% and 20%. Costly raw materials hurt early FY27, but price hikes, more premium products and the new in-house raw-material plant (VAM-VAE) slowly lift margins to 19.5% by FY31 — still below FY24's one-off peak of 21.4%.
B16: Treasury yield on opening cash & investments % | C16: 0.065 | D16: 0.065 | E16: 0.065 | F16: 0.065 | G16: 0.065 | H16: Interest/gains the cash pile earns: ~6.5% on liquid funds and treasury investments, applied to the OPENING balance each year — treasury income now follows the cash pile, not sales.
B17: Misc other income % of revenue | C17: 0.0075 | D17: 0.0075 | E17: 0.0075 | F17: 0.0075 | G17: 0.0075 | H17: Scrap sales, incentives, royalties etc. ~0.75% of sales. Calibration: 6.5% yield + 0.75% misc gives ₹625 Cr for FY26 vs ₹728 Cr actual (which had one-offs) — deliberately conservative.
B18: Depreciation % (opening block + ½ capex) | C18: 0.115 | D18: 0.115 | E18: 0.115 | F18: 0.115 | G18: 0.115 | H18: In FY26, depreciation was ~11.7% of the assets the year started with. We use 11.5%, and count only half a year's depreciation on assets bought during the year.
B19: Capex % of revenue | C19: 0.05 | D19: 0.045 | E19: 0.04 | F19: 0.04 | G19: 0.04 | H19: Spending on new factories (VAM-VAE) stays high in FY27–28 (5% / 4.5% of sales), then settles at ~4% of sales — enough for upkeep plus growth. FY24–26 averaged ~5.5% during the building phase. Roughly ₹1,300–1,500 Cr a year is maintenance (~2.5–3% of revenue); the rest is VAM-VAE completion and growth projects.
B20: Effective tax rate % | C20: 0.265 | D20: 0.265 | E20: 0.265 | F20: 0.265 | G20: 0.265 | H20: The company paid ~27% tax in FY25–26 and 24% in FY24. We use 26.5% for all forecast years.
B21: Receivable days (of revenue) | C21: 46 | D21: 46 | E21: 46 | F21: 46 | G21: 46 | H21: In FY26, customers took ~46 days to pay. With competition this high, the company can't force faster payment — so we keep it at 46 days.
B22: Inventory days (of operating costs) | C22: 72 | D22: 71 | E22: 70 | F22: 69 | G22: 68 | H22: FY26 actual: inventory ₹5,744 Cr ÷ operating costs ₹28,884 Cr × 365 ≈ 72.6 days. Stock relates to production COST, not sales price. Small yearly gains from the in-house raw-material plant, down to 68 days.
B23: Payable days (of operating costs) | C23: 49 | D23: 49 | E23: 49 | F23: 49 | G23: 49 | H23: FY26 actual: payables ₹3,863 Cr ÷ operating costs ₹28,884 Cr × 365 ≈ 48.8 days. Supplier dues arise from purchases, so they are measured against costs — held at 49 days.
B24: Interest rate on opening debt % | C24: 0.065 | D24: 0.065 | E24: 0.065 | F24: 0.065 | G24: 0.065 | H24: In FY26 the company paid ~₹195 Cr interest on ~₹3,100 Cr of average debt — roughly 6.3%. We round to 6.5%.
B25: New borrowings / (repayment) ₹ Cr | C25: 0 | D25: 0 | E25: 0 | F25: 0 | G25: 0 | H25: The company has more cash than debt and doesn't need loans. Borrowings (₹2,293 Cr) and lease liabilities (₹1,636 Cr) are both held flat at FY26 levels — leases keep getting renewed as old ones end.
B26: Dividend payout % of PAT | C26: 0.6 | D26: 0.6 | E26: 0.6 | F26: 0.6 | G26: 0.6 | H26: Over the last 5 years the company paid out 58–65% of its profit as dividend, even in bad years. We use 60%.
B27: Residual other assets / liabilities | C27: grow | D27: with | E27: revenue | H27: All the other small balance-sheet items (advances, deposits, provisions etc.) grow at the same speed as sales, starting from their FY26 levels.
B29: VALUATION INPUTS (DCF)
H30: Justification
B31: Risk-free rate % | C31: 0.065 | H31: 10-year G-Sec yield ~6.5% as of Aug-2026 (RBI/CCIL market data) — the return available with zero risk.
B32: Equity risk premium % | C32: 0.06 | H32: Long-run India equity risk premium ~6% — consistent with widely used academic/consensus estimates (e.g., Damodaran).
B33: Beta (times) | C33: 0.85 | H33: Raw beta vs Nifty 50 over 2–5 years is ~0.7–0.9 (exchange data); we use 0.85 with no adjustment.
B34: Cost of equity (CAPM) % | C34: =C31+C33*C32 -> 0.116 | H34: The return shareholders expect = risk-free rate + beta × extra return for shares.
B35: Pre-tax cost of debt % | C35: 0.075 | H35: The interest rate the company would pay if it took a new loan or lease today.
B36: Terminal growth rate % | C36: 0.045 | H36: Long-run inflation (~4%) plus up to half a percent of real growth. Kept deliberately conservative because it applies forever; the Bull scenario uses 5%.

Sheet Working Capital Schedule
A1: WORKING CAPITAL SCHEDULE | C1: Actual | D1: Forecasts
B2: (All figures in ₹ Crores except per-share data) | C2: FY26A | D2: FY27E | E2: FY28E | F2: FY29E | G2: FY30E | H2: FY31E
B4: DRIVERS
I5: Note
B6: Revenue | C6: ='Income Statement'!C4 -> 35584 | D6: ='Income Statement'!D4 -> 40210.899 | E6: ='Income Statement'!E4 -> 44643.748 | F6: ='Income Statement'!F4 -> 49119.842 | G6: ='Income Statement'!G4 -> 53793.349 | H6: ='Income Statement'!H4 -> 58636.23 | I6: from Income Statement
B7: Operating costs (COGS + opex) | C7: ='Income Statement'!C6 -> 28884 | D7: ='Income Statement'!D6 -> 32892.515 | E7: ='Income Statement'!E6 -> 36340.011 | F7: ='Income Statement'!F6 -> 39787.072 | G7: ='Income Statement'!G6 -> 43465.026 | H7: ='Income Statement'!H6 -> 47202.165 | I7: cost base for inventory & payables
B8: Receivable days | C8: =C14/C6*365 -> 45.821942 | D8: =Assumptions!C21 -> 46 | E8: =Assumptions!D21 -> 46 | F8: =Assumptions!E21 -> 46 | G8: =Assumptions!F21 -> 46 | H8: =Assumptions!G21 -> 46 | I8: FY26A = actual implied; forecasts from Assumptions
B9: Inventory days (of operating costs) | C9: =C15/C7*365 -> 72.581723 | D9: =Assumptions!C22 -> 72 | E9: =Assumptions!D22 -> 71 | F9: =Assumptions!E22 -> 70 | G9: =Assumptions!F22 -> 69 | H9: =Assumptions!G22 -> 68 | I9: FY26A = actual implied; forecasts from Assumptions
B10: Payable days (of operating costs) | C10: =C16/C7*365 -> 48.817044 | D10: =Assumptions!C23 -> 49 | E10: =Assumptions!D23 -> 49 | F10: =Assumptions!E23 -> 49 | G10: =Assumptions!F23 -> 49 | H10: =Assumptions!G23 -> 49 | I10: FY26A = actual implied; forecasts from Assumptions
B12: WORKING CAPITAL BALANCES
I13: Note
B14: Trade Receivables | C14: ='Balance Sheet'!C9 -> 4467.2 | D14: =D6*D8/365 -> 5067.6749 | E14: =E6*E8/365 -> 5626.3354 | F14: =F6*F8/365 -> 6190.4458 | G14: =G6*G8/365 -> 6779.4358 | H14: =H6*H8/365 -> 7389.7714 | I14: Revenue × receivable days ÷ 365
B15: Inventories | C15: ='Balance Sheet'!C8 -> 5743.7 | D15: =D7*D9/365 -> 6488.3865 | E15: =E7*E9/365 -> 7068.8788 | F15: =F7*F9/365 -> 7630.3973 | G15: =G7*G9/365 -> 8216.6762 | H15: =H7*H9/365 -> 8793.828 | I15: Operating costs × inventory days ÷ 365
B16: Trade Payables | C16: ='Balance Sheet'!C21 -> 3863.1 | D16: =D7*D10/365 -> 4415.7075 | E16: =E7*E10/365 -> 4878.522 | F16: =F7*F10/365 -> 5341.2781 | G16: =G7*G10/365 -> 5835.0309 | H16: =H7*H10/365 -> 6336.729 | I16: Operating costs × payable days ÷ 365
B17: Net Working Capital (Rec + Inv − Pay) | C17: =C14+C15-C16 -> 6347.8 | D17: =D14+D15-D16 -> 7140.3539 | E17: =E14+E15-E16 -> 7816.6922 | F17: =F14+F15-F16 -> 8479.565 | G17: =G14+G15-G16 -> 9161.081 | H17: =H14+H15-H16 -> 9846.8704
B18: (Increase)/decrease in NWC — cash impact | D18: =C17-D17 -> -792.55392 | E18: =D17-E17 -> -676.33827 | F18: =E17-F17 -> -662.87283 | G18: =F17-G17 -> -681.51603 | H18: =G17-H17 -> -685.78939 | I18: prior NWC − current NWC; negative = cash absorbed → feeds Cash Flow

Sheet Dep & Capex Schedule
A1: DEP & CAPEX SCHEDULE | C1: Actual | D1: Forecasts
B2: (All figures in ₹ Crores except per-share data) | C2: FY26A | D2: FY27E | E2: FY28E | F2: FY29E | G2: FY30E | H2: FY31E
B4: DRIVERS
I5: Note
B6: Revenue | C6: ='Income Statement'!C4 -> 35584 | D6: ='Income Statement'!D4 -> 40210.899 | E6: ='Income Statement'!E4 -> 44643.748 | F6: ='Income Statement'!F4 -> 49119.842 | G6: ='Income Statement'!G4 -> 53793.349 | H6: ='Income Statement'!H4 -> 58636.23
B7: Capex % of revenue | D7: =Assumptions!C19 -> 0.05 | E7: =Assumptions!D19 -> 0.045 | F7: =Assumptions!E19 -> 0.04 | G7: =Assumptions!F19 -> 0.04 | H7: =Assumptions!G19 -> 0.04
B8: Depreciation rate | D8: =Assumptions!C18 -> 0.115 | E8: =Assumptions!D18 -> 0.115 | F8: =Assumptions!E18 -> 0.115 | G8: =Assumptions!F18 -> 0.115 | H8: =Assumptions!G18 -> 0.115
B10: NET BLOCK ROLL-FORWARD (incl. CWIP)
I11: Note
B12: Opening Net Block | D12: ='Balance Sheet'!C6 -> 11489 | E12: =D15 -> 12062.704 | F12: =E15 -> 12568.946 | G12: =F15 -> 12975.335 | H12: =G15 -> 13511.181 | I12: FY27 opens at FY26 closing block; later years chain
B13: Add: Capex | C13: =-'Cash Flow'!C14 -> 1484 | D13: =D6*D7 -> 2010.5449 | E13: =E6*E7 -> 2008.9687 | F13: =F6*F7 -> 1964.7937 | G13: =G6*G7 -> 2151.734 | H13: =H6*H7 -> 2345.4492 | I13: Revenue × capex %; same figure flows to Cash Flow
B14: Less: Depreciation | C14: ='Income Statement'!C10 -> 1229 | D14: =D8*(D12+0.5*D13) -> 1436.8413 | E14: =E8*(E12+0.5*E13) -> 1502.7266 | F14: =F8*(F12+0.5*F13) -> 1558.4044 | G14: =G8*(G12+0.5*G13) -> 1615.8882 | H14: =H8*(H12+0.5*H13) -> 1688.6491 | I14: rate × (opening block + ½ × capex) → feeds Income Statement
B15: Closing Net Block | C15: ='Balance Sheet'!C6 -> 11489 | D15: =D12+D13-D14 -> 12062.704 | E15: =E12+E13-E14 -> 12568.946 | F15: =F12+F13-F14 -> 12975.335 | G15: =G12+G13-G14 -> 13511.181 | H15: =H12+H13-H14 -> 14167.981 | I15: → feeds Balance Sheet fixed assets

Sheet Debt Schedule
A1: DEBT SCHEDULE | C1: Actual | D1: Forecasts
B2: (All figures in ₹ Crores except per-share data) | C2: FY26A | D2: FY27E | E2: FY28E | F2: FY29E | G2: FY30E | H2: FY31E
B4: BORROWINGS (EX-LEASE) ROLL-FORWARD
I5: Note
B6: Opening Borrowings (ex-lease) | D6: ='Balance Sheet'!C19 -> 2293.4 | E6: =D8 -> 2293.4 | F6: =E8 -> 2293.4 | G6: =F8 -> 2293.4 | H6: =G8 -> 2293.4 | I6: FY27 opens at FY26 closing borrowings; later years chain
B7: Add: New borrowings / (repayment) | D7: =Assumptions!C25 -> 0 | E7: =Assumptions!D25 -> 0 | F7: =Assumptions!E25 -> 0 | G7: =Assumptions!F25 -> 0 | H7: =Assumptions!G25 -> 0 | I7: from Assumptions — nil
B8: Closing Borrowings (ex-lease) | C8: ='Balance Sheet'!C19 -> 2293.4 | D8: =D6+D7 -> 2293.4 | E8: =E6+E7 -> 2293.4 | F8: =F6+F7 -> 2293.4 | G8: =G6+G7 -> 2293.4 | H8: =H6+H7 -> 2293.4 | I8: → feeds Balance Sheet borrowings (ex-lease)
B9: Opening Lease Liabilities | D9: ='Balance Sheet'!C20 -> 1635.6 | E9: =D11 -> 1635.6 | F9: =E11 -> 1635.6 | G9: =F11 -> 1635.6 | H9: =G11 -> 1635.6
B10: Add: New leases / (repayments) net | D10: 0 | E10: 0 | F10: 0 | G10: 0 | H10: 0 | I10: lease renewals assumed to offset repayments
B11: Closing Lease Liabilities | C11: ='Balance Sheet'!C20 -> 1635.6 | D11: =D9+D10 -> 1635.6 | E11: =E9+E10 -> 1635.6 | F11: =F9+F10 -> 1635.6 | G11: =G9+G10 -> 1635.6 | H11: =H9+H10 -> 1635.6 | I11: → feeds Balance Sheet lease liabilities
B12: Total Closing Debt (borrowings + leases) | C12: =C8+C11 -> 3929 | D12: =D8+D11 -> 3929 | E12: =E8+E11 -> 3929 | F12: =F8+F11 -> 3929 | G12: =G8+G11 -> 3929 | H12: =H8+H11 -> 3929
B15: INTEREST EXPENSE
I16: Note
B17: Interest rate on opening debt | D17: =Assumptions!C24 -> 0.065 | E17: =Assumptions!D24 -> 0.065 | F17: =Assumptions!E24 -> 0.065 | G17: =Assumptions!F24 -> 0.065 | H17: =Assumptions!G24 -> 0.065
B18: Interest Expense | C18: ='Income Statement'!C11 -> 195 | D18: =D17*(D6+D9) -> 255.385 | E18: =E17*(E6+E9) -> 255.385 | F18: =F17*(F6+F9) -> 255.385 | G18: =G17*(G6+G9) -> 255.385 | H18: =H17*(H6+H9) -> 255.385 | I18: rate × (opening borrowings + opening leases) → feeds Income Statement

Sheet Income Statement
A1: INCOME STATEMENT | C1: Actual | D1: Forecasts
B2: (All figures in ₹ Crores except per-share data) | C2: FY26A | D2: FY27E | E2: FY28E | F2: FY29E | G2: FY30E | H2: FY31E
I3: Note
B4: Revenue from Operations | C4: ='Historical Data'!G6 -> 35584 | D4: =C4*(1+Assumptions!C14) -> 40210.899 | E4: =D4*(1+Assumptions!D14) -> 44643.748 | F4: =E4*(1+Assumptions!E14) -> 49119.842 | G4: =F4*(1+Assumptions!F14) -> 53793.349 | H4: =G4*(1+Assumptions!G14) -> 58636.23
B5: Revenue growth % | D5: =D4/C4-1 -> 0.1300275 | E5: =E4/D4-1 -> 0.11024 | F5: =F4/E4-1 -> 0.1002625 | G5: =G4/F4-1 -> 0.095145 | H5: =H4/G4-1 -> 0.0900275 | I5: FY27 growth on FY26 actual
B6: Total Operating Expenses | C6: =C4-C7 -> 28884 | D6: =D4-D7 -> 32892.515 | E6: =E4-E7 -> 36340.011 | F6: =F4-F7 -> 39787.072 | G6: =G4-G7 -> 43465.026 | H6: =H4-H7 -> 47202.165 | I6: Revenue − EBITDA
B7: EBITDA | C7: ='Historical Data'!G8 -> 6700 | D7: =D4*Assumptions!C15 -> 7318.3835 | E7: =E4*Assumptions!D15 -> 8303.7371 | F7: =F4*Assumptions!E15 -> 9332.7699 | G7: =G4*Assumptions!F15 -> 10328.323 | H7: =H4*Assumptions!G15 -> 11434.065 | I7: Revenue × EBITDA margin assumption
B8: EBITDA margin % | C8: =C7/C4 -> 0.18828687 | D8: =D7/D4 -> 0.182 | E8: =E7/E4 -> 0.186 | F8: =F7/F4 -> 0.19 | G8: =G7/G4 -> 0.192 | H8: =H7/H4 -> 0.195
B9: Other Income | C9: ='Historical Data'!G10 -> 728 | D9: =Assumptions!C16*('Balance Sheet'!C10+'Balance Sheet'!C7)+Assumptions!C17*D4 -> 830.40874 | E9: =Assumptions!D16*('Balance Sheet'!D10+'Balance Sheet'!D7)+Assumptions!D17*E4 -> 903.90957 | F9: =Assumptions!E16*('Balance Sheet'!E10+'Balance Sheet'!E7)+Assumptions!E17*F4 -> 1008.4113 | G9: =Assumptions!F16*('Balance Sheet'!F10+'Balance Sheet'!F7)+Assumptions!F17*G4 -> 1142.4103 | H9: =Assumptions!G16*('Balance Sheet'!G10+'Balance Sheet'!G7)+Assumptions!G17*H4 -> 1288.7824 | I9: treasury yield × opening (cash + investments) + misc % of revenue
B10: Depreciation & Amortisation | C10: ='Historical Data'!G12 -> 1229 | D10: ='Dep & Capex Schedule'!D14 -> 1436.8413 | E10: ='Dep & Capex Schedule'!E14 -> 1502.7266 | F10: ='Dep & Capex Schedule'!F14 -> 1558.4044 | G10: ='Dep & Capex Schedule'!G14 -> 1615.8882 | H10: ='Dep & Capex Schedule'!H14 -> 1688.6491 | I10: from Dep-Capex Schedule
B11: Interest (Finance Costs) | C11: ='Historical Data'!G11 -> 195 | D11: ='Debt Schedule'!D18 -> 255.385 | E11: ='Debt Schedule'!E18 -> 255.385 | F11: ='Debt Schedule'!F18 -> 255.385 | G11: ='Debt Schedule'!G18 -> 255.385 | H11: ='Debt Schedule'!H18 -> 255.385 | I11: from Debt Schedule
B12: Profit Before Tax | C12: =C7+C9-C10-C11 -> 6004 | D12: =D7+D9-D10-D11 -> 6456.5659 | E12: =E7+E9-E10-E11 -> 7449.5351 | F12: =F7+F9-F10-F11 -> 8527.3919 | G12: =G7+G9-G10-G11 -> 9599.4601 | H12: =H7+H9-H10-H11 -> 10778.813 | I12: EBITDA + other income − dep − interest
B13: Less: Tax (net of associates/MI) | C13: =C12-C14 -> 1609 | D13: =D12*Assumptions!C20 -> 1710.99 | E13: =E12*Assumptions!D20 -> 1974.1268 | F13: =F12*Assumptions!E20 -> 2259.7588 | G13: =G12*Assumptions!F20 -> 2543.8569 | H13: =H12*Assumptions!G20 -> 2856.3855 | I13: PBT × 26.5% (Assumptions)
B14: Net Profit | C14: ='Historical Data'!G15 -> 4395 | D14: =D12-D13 -> 4745.576 | E14: =E12-E13 -> 5475.4083 | F14: =F12-F13 -> 6267.633 | G14: =G12-G13 -> 7055.6032 | H14: =H12-H13 -> 7922.4277 | I14: pending schedules
B15: Net margin % | C15: =C14/C4 -> 0.12351057 | D15: =D14/D4 -> 0.11801716 | E15: =E14/E4 -> 0.1226467 | F15: =F14/F4 -> 0.1275988 | G15: =G14/G4 -> 0.13116125 | H15: =H14/H4 -> 0.13511148
B16: EPS (₹) | C16: ='Historical Data'!G17 -> 45.09 | D16: =D14/Assumptions!$C$8 -> 49.474312 | E16: =E14/Assumptions!$C$8 -> 57.083072 | F16: =F14/Assumptions!$C$8 -> 65.342296 | G16: =G14/Assumptions!$C$8 -> 73.557164 | H16: =H14/Assumptions!$C$8 -> 82.594117 | I16: forecast: Net Profit ÷ shares outstanding
B17: Dividend per Share (₹) | C17: =C16*'Historical Data'!G18 -> 27.5049 | D17: =D16*Assumptions!C26 -> 29.684587 | E17: =E16*Assumptions!D26 -> 34.249843 | F17: =F16*Assumptions!E26 -> 39.205378 | G17: =G16*Assumptions!F26 -> 44.134298 | H17: =H16*Assumptions!G26 -> 49.55647 | I17: forecast: EPS × 60% payout
B19: Depreciation, interest and everything below them will fill automatically once the Dep-Capex and Debt schedules are built (rest of Part 5).

Sheet Balance Sheet
A1: BALANCE SHEET | C1: Actual | D1: Forecasts
B2: (All figures in ₹ Crores except per-share data) | C2: FY26A | D2: FY27E | E2: FY28E | F2: FY29E | G2: FY30E | H2: FY31E
B4: ASSETS
I5: Note
B6: Net Fixed Assets + CWIP | C6: ='Historical Data'!G29+'Historical Data'!G30 -> 11489 | D6: ='Dep & Capex Schedule'!D15 -> 12062.704 | E6: ='Dep & Capex Schedule'!E15 -> 12568.946 | F6: ='Dep & Capex Schedule'!F15 -> 12975.335 | G6: ='Dep & Capex Schedule'!G15 -> 13511.181 | H6: ='Dep & Capex Schedule'!H15 -> 14167.981 | I6: → from Dep-Capex Schedule
B7: Investments (non-current + current) | C7: ='Historical Data'!G31 -> 7062 | D7: =C7 -> 7062 | E7: =C7 -> 7062 | F7: =C7 -> 7062 | G7: =C7 -> 7062 | H7: =C7 -> 7062 | I7: held at FY26 level; surplus cash builds in the cash line
B8: Inventories | C8: ='Historical Data'!E55 -> 5743.7 | D8: ='Working Capital Schedule'!D15 -> 6488.3865 | E8: ='Working Capital Schedule'!E15 -> 7068.8788 | F8: ='Working Capital Schedule'!F15 -> 7630.3973 | G8: ='Working Capital Schedule'!G15 -> 8216.6762 | H8: ='Working Capital Schedule'!H15 -> 8793.828 | I8: → from Working Capital Schedule
B9: Trade Receivables | C9: ='Historical Data'!E56 -> 4467.2 | D9: ='Working Capital Schedule'!D14 -> 5067.6749 | E9: ='Working Capital Schedule'!E14 -> 5626.3354 | F9: ='Working Capital Schedule'!F14 -> 6190.4458 | G9: ='Working Capital Schedule'!G14 -> 6779.4358 | H9: ='Working Capital Schedule'!H14 -> 7389.7714 | I9: → from Working Capital Schedule
B10: Cash & Cash Equivalents | C10: ='Historical Data'!E57 -> 1073.8 | D10: ='Cash Flow'!D28 -> 1693.0993 | E10: ='Cash Flow'!E28 -> 2784.3464 | F10: ='Cash Flow'!F28 -> 4306.6177 | G10: ='Cash Flow'!G28 -> 5999.7034 | H10: ='Cash Flow'!H28 -> 7917.4878 | I10: closing cash from Cash Flow — the model's plug
B11: Other Assets (residual) | C11: ='Historical Data'!G32-C8-C9-C10 -> 4683.3 | D11: =C11*(1+Assumptions!C14) -> 5292.2578 | E11: =D11*(1+Assumptions!D14) -> 5875.6763 | F11: =E11*(1+Assumptions!E14) -> 6464.7863 | G11: =F11*(1+Assumptions!F14) -> 7079.8784 | H11: =G11*(1+Assumptions!G14) -> 7717.2621 | I11: grows with revenue (Assumptions)
B12: TOTAL ASSETS | C12: =SUM(C6:C11) -> 34519 | D12: =SUM(D6:D11) -> 37666.122 | E12: =SUM(E6:E11) -> 40986.183 | F12: =SUM(F6:F11) -> 44629.582 | G12: =SUM(G6:G11) -> 48648.874 | H12: =SUM(H6:H11) -> 53048.33 | I12: sum of all asset lines
B14: EQUITY & LIABILITIES
I15: Note
B16: Equity Share Capital | C16: ='Historical Data'!G23 -> 96 | D16: =C16 -> 96 | E16: =C16 -> 96 | F16: =C16 -> 96 | G16: =C16 -> 96 | H16: =C16 -> 96 | I16: constant — no buyback/split assumed
B17: Reserves & Surplus | C17: ='Historical Data'!G24 -> 21276 | D17: =C17+'Income Statement'!D14*(1-Assumptions!C26) -> 23174.23 | E17: =D17+'Income Statement'!E14*(1-Assumptions!D26) -> 25364.394 | F17: =E17+'Income Statement'!F14*(1-Assumptions!E26) -> 27871.447 | G17: =F17+'Income Statement'!G14*(1-Assumptions!F26) -> 30693.688 | H17: =G17+'Income Statement'!H14*(1-Assumptions!G26) -> 33862.659 | I17: prior reserves + PAT retained (40%)
B18: Net Worth | C18: =C16+C17 -> 21372 | D18: =D16+D17 -> 23270.23 | E18: =E16+E17 -> 25460.394 | F18: =F16+F17 -> 27967.447 | G18: =G16+G17 -> 30789.688 | H18: =H16+H17 -> 33958.659
B19: Borrowings (ex-lease) | C19: ='Historical Data'!E61 -> 2293.4 | D19: ='Debt Schedule'!D8 -> 2293.4 | E19: ='Debt Schedule'!E8 -> 2293.4 | F19: ='Debt Schedule'!F8 -> 2293.4 | G19: ='Debt Schedule'!G8 -> 2293.4 | H19: ='Debt Schedule'!H8 -> 2293.4 | I19: → from Debt Schedule (ex-lease roll-forward)
B20: Lease Liabilities | C20: ='Historical Data'!E62 -> 1635.6 | D20: ='Debt Schedule'!D11 -> 1635.6 | E20: ='Debt Schedule'!E11 -> 1635.6 | F20: ='Debt Schedule'!F11 -> 1635.6 | G20: ='Debt Schedule'!G11 -> 1635.6 | H20: ='Debt Schedule'!H11 -> 1635.6 | I20: → from Debt Schedule (lease roll-forward)
B21: Trade Payables | C21: ='Historical Data'!E59 -> 3863.1 | D21: ='Working Capital Schedule'!D16 -> 4415.7075 | E21: ='Working Capital Schedule'!E16 -> 4878.522 | F21: ='Working Capital Schedule'!F16 -> 5341.2781 | G21: ='Working Capital Schedule'!G16 -> 5835.0309 | H21: ='Working Capital Schedule'!H16 -> 6336.729 | I21: → from Working Capital Schedule
B22: Other Liabilities (residual) | C22: ='Historical Data'!G27-C21 -> 5354.9 | D22: =C22*(1+Assumptions!C14) -> 6051.1843 | E22: =D22*(1+Assumptions!D14) -> 6718.2668 | F22: =E22*(1+Assumptions!E14) -> 7391.857 | G22: =F22*(1+Assumptions!F14) -> 8095.1553 | H22: =G22*(1+Assumptions!G14) -> 8823.9419 | I22: grows with revenue (Assumptions)
B23: TOTAL EQUITY & LIABILITIES | C23: =C18+C19+C20+C21+C22 -> 34519 | D23: =D18+D19+D20+D21+D22 -> 37666.122 | E23: =E18+E19+E20+E21+E22 -> 40986.183 | F23: =F18+F19+F20+F21+F22 -> 44629.582 | G23: =G18+G19+G20+G21+G22 -> 48648.874 | H23: =H18+H19+H20+H21+H22 -> 53048.33
B24: Balance Check (must be 0) | C24: =C23-C12 -> 0 | D24: =D23-D12 -> 0 | E24: =E23-E12 -> 0 | F24: =F23-F12 -> 0 | G24: =G23-G12 -> 0 | H24: =H23-H12 -> 0 | I24: The integrated three-statement model balances with a ₹0 balance-sheet check across all forecast years; closing cash is derived from the cash-flow statement.

Sheet Cash Flow
A1: CASH FLOW STATEMENT | C1: Actual | D1: Forecasts
B2: (All figures in ₹ Crores except per-share data) | C2: FY26A | D2: FY27E | E2: FY28E | F2: FY29E | G2: FY30E | H2: FY31E
B4: OPERATING ACTIVITIES
I5: Note
B6: Net Profit | C6: ='Historical Data'!G15 -> 4395 | D6: ='Income Statement'!D14 -> 4745.576 | E6: ='Income Statement'!E14 -> 5475.4083 | F6: ='Income Statement'!F14 -> 6267.633 | G6: ='Income Statement'!G14 -> 7055.6032 | H6: ='Income Statement'!H14 -> 7922.4277 | I6: → from completed Income Statement
B7: Add: Depreciation & Amortisation | C7: ='Historical Data'!G12 -> 1229 | D7: ='Dep & Capex Schedule'!D14 -> 1436.8413 | E7: ='Dep & Capex Schedule'!E14 -> 1502.7266 | F7: ='Dep & Capex Schedule'!F14 -> 1558.4044 | G7: ='Dep & Capex Schedule'!G14 -> 1615.8882 | H7: ='Dep & Capex Schedule'!H14 -> 1688.6491 | I7: → from Dep-Capex Schedule
B8: (Increase)/decrease in working capital | D8: ='Working Capital Schedule'!D18 -> -792.55392 | E8: ='Working Capital Schedule'!E18 -> -676.33827 | F8: ='Working Capital Schedule'!F18 -> -662.87283 | G8: ='Working Capital Schedule'!G18 -> -681.51603 | H8: ='Working Capital Schedule'!H18 -> -685.78939 | I8: → from Working Capital Schedule
B9: Other operating adjustments (net) | C9: ='Historical Data'!G38-C6-C7 -> 1464 | D9: =('Balance Sheet'!D22-'Balance Sheet'!C22)-('Balance Sheet'!D11-'Balance Sheet'!C11) -> 87.326469 | E9: =('Balance Sheet'!E22-'Balance Sheet'!D22)-('Balance Sheet'!E11-'Balance Sheet'!D11) -> 83.664054 | F9: =('Balance Sheet'!F22-'Balance Sheet'!E22)-('Balance Sheet'!F11-'Balance Sheet'!E11) -> 84.480232 | G9: =('Balance Sheet'!G22-'Balance Sheet'!F22)-('Balance Sheet'!G11-'Balance Sheet'!F11) -> 88.206147 | H9: =('Balance Sheet'!H22-'Balance Sheet'!G22)-('Balance Sheet'!H11-'Balance Sheet'!G11) -> 91.402841 | I9: change in residual other liabilities − change in residual other assets (non-WC, non-cash items)
B10: Cash from Operating Activities | C10: ='Historical Data'!G38 -> 7088 | D10: =SUM(D6:D9) -> 5477.1899 | E10: =SUM(E6:E9) -> 6385.4607 | F10: =SUM(F6:F9) -> 7247.6448 | G10: =SUM(G6:G9) -> 8078.1815 | H10: =SUM(H6:H9) -> 9016.6902 | I10: Why FY27E CFO (~₹5,500 Cr) is below FY26A (₹7,088 Cr): FY26 enjoyed a one-off working-capital RELEASE (~₹1,460 Cr), while FY27 must fund ~₹790 Cr of extra working capital for 13% growth; tax outgo also rises with profit.
B12: INVESTING ACTIVITIES
I13: Note
B14: Capex (additions to fixed assets & CWIP) | C14: =-('Historical Data'!G38-'Historical Data'!G42) -> -1484 | D14: =-'Income Statement'!D4*Assumptions!C19 -> -2010.5449 | E14: =-'Income Statement'!E4*Assumptions!D19 -> -2008.9687 | F14: =-'Income Statement'!F4*Assumptions!E19 -> -1964.7937 | G14: =-'Income Statement'!G4*Assumptions!F19 -> -2151.734 | H14: =-'Income Statement'!H4*Assumptions!G19 -> -2345.4492 | I14: FY26A shown on screener's FCF definition (CFO − FCF); company-reported FY26 gross PP&E purchases were ~₹2,243 Cr (ICICI). Forecasts use capex % of revenue, so they are unaffected.
B15: Change in investments / others (net) | C15: ='Historical Data'!G39-C14 -> 156 | D15: 0 | E15: 0 | F15: 0 | G15: 0 | H15: 0 | I15: investment book held flat in forecasts
B16: Cash from Investing Activities | C16: ='Historical Data'!G39 -> -1328 | D16: =D14+D15 -> -2010.5449 | E16: =E14+E15 -> -2008.9687 | F16: =F14+F15 -> -1964.7937 | G16: =G14+G15 -> -2151.734 | H16: =H14+H15 -> -2345.4492
B18: FINANCING ACTIVITIES
I19: Note
B20: New borrowings / (repayment) | C20: ='Historical Data'!G26-'Historical Data'!F26 -> 1639 | D20: =Assumptions!C25 -> 0 | E20: =Assumptions!D25 -> 0 | F20: =Assumptions!E25 -> 0 | G20: =Assumptions!F25 -> 0 | H20: =Assumptions!G25 -> 0 | I20: Assumptions: debt held flat → nil flows
B21: Dividends, interest & lease payments (net) | C21: ='Historical Data'!G40-C20 -> -4016 | D21: =-'Income Statement'!D14*Assumptions!C26 -> -2847.3456 | E21: =-'Income Statement'!E14*Assumptions!D26 -> -3285.245 | F21: =-'Income Statement'!F14*Assumptions!E26 -> -3760.5798 | G21: =-'Income Statement'!G14*Assumptions!F26 -> -4233.3619 | H21: =-'Income Statement'!H14*Assumptions!G26 -> -4753.4566 | I21: forecast = dividends only (interest & leases already inside PAT)
B22: Cash from Financing Activities | C22: ='Historical Data'!G40 -> -2377 | D22: =D20+D21 -> -2847.3456 | E22: =E20+E21 -> -3285.245 | F22: =F20+F21 -> -3760.5798 | G22: =G20+G21 -> -4233.3619 | H22: =H20+H21 -> -4753.4566 | I22: forecast: borrowings − dividends − interest
B24: NET CASH FLOW
I25: Note
B26: Net Change in Cash | C26: ='Historical Data'!G41 -> 3383 | D26: =D10+D16+D22 -> 619.29935 | E26: =E10+E16+E22 -> 1091.247 | F26: =F10+F16+F22 -> 1522.2713 | G26: =G10+G16+G22 -> 1693.0856 | H26: =H10+H16+H22 -> 1917.7844 | I26: CFO + CFI + CFF
B27: Opening Cash | D27: ='Balance Sheet'!C10 -> 1073.8 | E27: =D28 -> 1693.0993 | F27: =E28 -> 2784.3464 | G27: =F28 -> 4306.6177 | H27: =G28 -> 5999.7034 | I27: FY27 opens at the FY26 balance-sheet cash; later years chain from closing
B28: Closing Cash | D28: =D27+D26 -> 1693.0993 | E28: =E27+E26 -> 2784.3464 | F28: =F27+F26 -> 4306.6177 | G28: =G27+G26 -> 5999.7034 | H28: =H27+H26 -> 7917.4878 | I28: → feeds the Balance Sheet cash line (the model's plug)
B29: Free Cash Flow (CFO − capex) | C29: =C10+C14 -> 5604 | D29: =D10+D14 -> 3466.6449 | E29: =E10+E14 -> 4376.492 | F29: =F10+F14 -> 5282.8511 | G29: =G10+G14 -> 5926.4475 | H29: =H10+H14 -> 6671.241 | I29: check row; FY26A = ₹5,604 Cr per screener
B31: Note: screener's FY26A 'net change in cash' (₹3,383 Cr) uses a wider cash definition (incl. bank balances/deposits) than the ₹1,074 Cr cash line; the forecast roll-forward anchors on the balance-sheet figure.

Sheet Valuation
A1: VALUATION
B2: (All figures in ₹ Crores except per-share data)
B4: 1. COST OF CAPITAL (WACC) | I4: Note
B5: Market value of equity | C5: =Assumptions!C7*Assumptions!C8 -> 252077.76 | I5: share price × number of shares
B6: Market value of debt (incl. leases, FY26) | C6: ='Balance Sheet'!C19+'Balance Sheet'!C20 -> 3929 | I6: book value used as proxy
B7: Total capital | C7: =C5+C6 -> 256006.76
B8: Weight of equity | C8: =C5/C7 -> 0.98465275
B9: Weight of debt | C9: =C6/C7 -> 0.015347251
B10: Cost of equity (Ke) | C10: =Assumptions!C34 -> 0.116 | I10: from Assumptions (CAPM)
B11: Post-tax cost of debt | C11: =Assumptions!C35*(1-Assumptions!C20) -> 0.055125 | I11: 7.5% × (1 − 26.5% tax)
B12: WACC | C12: =C8*C10+C9*C11 -> 0.11506574 | I12: the blended return the company must earn for its investors
B14: 2. DISCOUNTED CASH FLOW (FCFF)
C15: FY27E | D15: FY28E | E15: FY29E | F15: FY30E | G15: FY31E
B16: EBITDA | C16: ='Income Statement'!D7 -> 7318.3835 | D16: ='Income Statement'!E7 -> 8303.7371 | E16: ='Income Statement'!F7 -> 9332.7699 | F16: ='Income Statement'!G7 -> 10328.323 | G16: ='Income Statement'!H7 -> 11434.065
B17: Less: Depreciation | C17: =-'Dep & Capex Schedule'!D14 -> -1436.8413 | D17: =-'Dep & Capex Schedule'!E14 -> -1502.7266 | E17: =-'Dep & Capex Schedule'!F14 -> -1558.4044 | F17: =-'Dep & Capex Schedule'!G14 -> -1615.8882 | G17: =-'Dep & Capex Schedule'!H14 -> -1688.6491
B18: EBIT | C18: =C16+C17 -> 5881.5422 | D18: =D16+D17 -> 6801.0105 | E18: =E16+E17 -> 7774.3656 | F18: =F16+F17 -> 8712.4348 | G18: =G16+G17 -> 9745.4157 | I18: other income excluded — treasury cash is added separately below
B19: NOPAT = EBIT × (1 − tax) | C19: =C18*(1-Assumptions!C20) -> 4322.9335 | D19: =D18*(1-Assumptions!D20) -> 4998.7427 | E19: =E18*(1-Assumptions!E20) -> 5714.1587 | F19: =F18*(1-Assumptions!F20) -> 6403.6396 | G19: =G18*(1-Assumptions!G20) -> 7162.8806
B20: Add: Depreciation | C20: =-C17 -> 1436.8413 | D20: =-D17 -> 1502.7266 | E20: =-E17 -> 1558.4044 | F20: =-F17 -> 1615.8882 | G20: =-G17 -> 1688.6491
B21: Less: Capex | C21: =-'Dep & Capex Schedule'!D13 -> -2010.5449 | D21: =-'Dep & Capex Schedule'!E13 -> -2008.9687 | E21: =-'Dep & Capex Schedule'!F13 -> -1964.7937 | F21: =-'Dep & Capex Schedule'!G13 -> -2151.734 | G21: =-'Dep & Capex Schedule'!H13 -> -2345.4492
B22: Add: Working-capital change | C22: ='Working Capital Schedule'!D18 -> -792.55392 | D22: ='Working Capital Schedule'!E18 -> -676.33827 | E22: ='Working Capital Schedule'!F18 -> -662.87283 | F22: ='Working Capital Schedule'!G18 -> -681.51603 | G22: ='Working Capital Schedule'!H18 -> -685.78939 | I22: negative = cash absorbed by growth
B23: Free Cash Flow to Firm (FCFF) | C23: =C19+C20+C21+C22 -> 2956.676 | D23: =D19+D20+D21+D22 -> 3816.1624 | E23: =E19+E20+E21+E22 -> 4644.8966 | F23: =F19+F20+F21+F22 -> 5186.2778 | G23: =G19+G20+G21+G22 -> 5820.2911 | I23: FCFF represents operating cash flows only; non-operating cash and investments are added separately in the EV-to-equity bridge.
B24: Discount period (mid-year) | C24: 0.5 | D24: 1.5 | E24: 2.5 | F24: 3.5 | G24: 4.5 | I24: cash arrives through the year, not on 31 March
B25: Discount factor | C25: =1/(1+$C$12)^C24 -> 0.94699953 | D25: =1/(1+$C$12)^D24 -> 0.84927686 | E25: =1/(1+$C$12)^E24 -> 0.76163838 | F25: =1/(1+$C$12)^F24 -> 0.68304348 | G25: =1/(1+$C$12)^G24 -> 0.61255894
B26: PV of FCFF | C26: =C23*C25 -> 2799.9708 | D26: =D23*D25 -> 3240.9784 | E26: =E23*E25 -> 3537.7315 | F26: =F23*F25 -> 3542.4533 | G26: =G23*G25 -> 3565.2713
B28: Sum of PV, FY27E–FY31E | C28: =SUM(C26:G26) -> 16686.405
B29: Terminal growth rate (g) | C29: =Assumptions!C36 -> 0.045 | I29: from Assumptions
B30: Terminal value at FY31 | C30: =G23*(1+C29)/($C$12-C29) -> 86807.112 | I30: FY31 cash flow growing at g forever
B31: PV of terminal value | C31: =C30*G25 -> 53174.472 | I31: ≈76% of enterprise value comes from the terminal value — treat the DCF as a cross-check and read it together with the sensitivity grid, not as a precise intrinsic value.
B32: Enterprise Value | C32: =C28+C31 -> 69860.877
B33: Add: Cash + investments (FY26) | C33: ='Balance Sheet'!C10+'Balance Sheet'!C7 -> 8135.8 | I33: Composition: cash ₹1,073.8 Cr + current investments ₹6,285.8 Cr + non-current investments ₹776.1 Cr — same consolidated basis throughout
B34: Less: Debt incl. leases (FY26) | C34: =-C6 -> -3929
B35: Equity Value | C35: =C32+C33+C34 -> 74067.677
B36: Shares outstanding (Cr) | C36: =Assumptions!C8 -> 95.92
B37: DCF INTRINSIC VALUE PER SHARE (₹) | C37: =C35/C36 -> 772.18179
B38: CMP premium over DCF value | C38: =Assumptions!C7/C37-1 -> 2.4033437 | I38: how much extra the market pays vs pure DCF maths
B40: 3. DCF SENSITIVITY — intrinsic value per share (₹)
B42: WACC ↓ \ Terminal growth → | C42: 0.035 | D42: 0.04 | E42: 0.045 | F42: 0.05 | G42: 0.055
B43: 0.105 | C43: =(SUMPRODUCT($C$23:$G$23/(1+$B43)^{0.5,1.5,2.5,3.5,4.5})+$G$23*(1+C$42)/($B43-C$42)/(1+$B43)^4.5+$C$33+$C$34)/$C$36 -> 794.46238 | D43: =(SUMPRODUCT($C$23:$G$23/(1+$B43)^{0.5,1.5,2.5,3.5,4.5})+$G$23*(1+D$42)/($B43-D$42)/(1+$B43)^4.5+$C$33+$C$34)/$C$36 -> 841.47627 | E43: =(SUMPRODUCT($C$23:$G$23/(1+$B43)^{0.5,1.5,2.5,3.5,4.5})+$G$23*(1+E$42)/($B43-E$42)/(1+$B43)^4.5+$C$33+$C$34)/$C$36 -> 896.3258 | F43: =(SUMPRODUCT($C$23:$G$23/(1+$B43)^{0.5,1.5,2.5,3.5,4.5})+$G$23*(1+F$42)/($B43-F$42)/(1+$B43)^4.5+$C$33+$C$34)/$C$36 -> 961.14798 | G43: =(SUMPRODUCT($C$23:$G$23/(1+$B43)^{0.5,1.5,2.5,3.5,4.5})+$G$23*(1+G$42)/($B43-G$42)/(1+$B43)^4.5+$C$33+$C$34)/$C$36 -> 1038.9346
B44: 0.11 | C44: =(SUMPRODUCT($C$23:$G$23/(1+$B44)^{0.5,1.5,2.5,3.5,4.5})+$G$23*(1+C$42)/($B44-C$42)/(1+$B44)^4.5+$C$33+$C$34)/$C$36 -> 743.45582 | D44: =(SUMPRODUCT($C$23:$G$23/(1+$B44)^{0.5,1.5,2.5,3.5,4.5})+$G$23*(1+D$42)/($B44-D$42)/(1+$B44)^4.5+$C$33+$C$34)/$C$36 -> 783.56242 | E44: =(SUMPRODUCT($C$23:$G$23/(1+$B44)^{0.5,1.5,2.5,3.5,4.5})+$G$23*(1+E$42)/($B44-E$42)/(1+$B44)^4.5+$C$33+$C$34)/$C$36 -> 829.83926 | F44: =(SUMPRODUCT($C$23:$G$23/(1+$B44)^{0.5,1.5,2.5,3.5,4.5})+$G$23*(1+F$42)/($B44-F$42)/(1+$B44)^4.5+$C$33+$C$34)/$C$36 -> 883.82891 | G44: =(SUMPRODUCT($C$23:$G$23/(1+$B44)^{0.5,1.5,2.5,3.5,4.5})+$G$23*(1+G$42)/($B44-G$42)/(1+$B44)^4.5+$C$33+$C$34)/$C$36 -> 947.63486
B45: 0.115 | C45: =(SUMPRODUCT($C$23:$G$23/(1+$B45)^{0.5,1.5,2.5,3.5,4.5})+$G$23*(1+C$42)/($B45-C$42)/(1+$B45)^4.5+$C$33+$C$34)/$C$36 -> 698.85018 | D45: =(SUMPRODUCT($C$23:$G$23/(1+$B45)^{0.5,1.5,2.5,3.5,4.5})+$G$23*(1+D$42)/($B45-D$42)/(1+$B45)^4.5+$C$33+$C$34)/$C$36 -> 733.39574 | E45: =(SUMPRODUCT($C$23:$G$23/(1+$B45)^{0.5,1.5,2.5,3.5,4.5})+$G$23*(1+E$42)/($B45-E$42)/(1+$B45)^4.5+$C$33+$C$34)/$C$36 -> 772.87638 | F45: =(SUMPRODUCT($C$23:$G$23/(1+$B45)^{0.5,1.5,2.5,3.5,4.5})+$G$23*(1+F$42)/($B45-F$42)/(1+$B45)^4.5+$C$33+$C$34)/$C$36 -> 818.43097 | G45: =(SUMPRODUCT($C$23:$G$23/(1+$B45)^{0.5,1.5,2.5,3.5,4.5})+$G$23*(1+G$42)/($B45-G$42)/(1+$B45)^4.5+$C$33+$C$34)/$C$36 -> 871.57798
...

Sheet Recommendation
A1: INVESTMENT RECOMMENDATION
B2: (All figures in ₹ Crores except per-share data)
A4: RECOMMENDATION
B5: Current market price (₹) | C5: =Assumptions!C7 -> 2628
